Workbook
Name Slicer_Channel: #N/A
Name Slicer_Customer_Segment: #N/A
Name Slicer_Month: #N/A

Sheet Raw_Data
A1: Date | B1: Channel | C1: Campaign Name | D1: Customer Segment | E1: Product ID | F1: Impressions | G1: Clicks | H1: Spend | I1: Conversions | J1: Revenue | K1: CTR (%) | L1: Conversion Rate (%) | M1: CPC ($) | N1: CPA ($) | O1: ROAS
A2: 45206 | B2: Google Ads | C2: Campaign 11 | D2: Freelancer | E2: P007 | F2: 30184 | G2: 1790 | H2: 7693.29 | I2: 302 | J2: 36765 | K2: 5.93 | L2: 16.87 | M2: 4.3 | N2: 25.47 | O2: 4.78
A3: 45262 | B3: Google Ads | C3: Campaign 30 | D3: Small Business | E3: P015 | F3: 73097 | G3: 2019 | H3: 2098.91 | I3: 82 | J3: 14260.16 | K3: 2.76 | L3: 4.06 | M3: 1.04 | N3: 25.6 | O3: 6.79
A4: 45235 | B4: Google Ads | C4: Campaign 34 | D4: Agency | E4: P006 | F4: 59513 | G4: 5484 | H4: 18114.19 | I4: 185 | J4: 35914.5 | K4: 9.21 | L4: 3.37 | M4: 3.3 | N4: 97.91 | O4: 1.98
A5: 45373 | B5: Google Ads | C5: Campaign 27 | D5: Freelancer | E5: P021 | F5: 27868 | G5: 3503 | H5: 4450.88 | I5: 226 | J5: 9212.64 | K5: 12.57 | L5: 6.45 | M5: 1.27 | N5: 19.69 | O5: 2.07
A6: 45222 | B6: Google Ads | C6: Campaign 43 | D6: Agency | E6: P021 | F6: 143964 | G6: 7070 | H6: 18039.11 | I6: 792 | J6: 48937.43 | K6: 4.91 | L6: 11.2 | M6: 2.55 | N6: 22.78 | O6: 2.71
A7: 45208 | B7: Google Ads | C7: Campaign 34 | D7: Agency | E7: P014 | F7: 111604 | G7: 10459 | H7: 10165.36 | I7: 894 | J7: 68337.86 | K7: 9.37 | L7: 8.55 | M7: 0.97 | N7: 11.37 | O7: 6.72
A8: 45223 | B8: Google Ads | C8: Campaign 7 | D8: Freelancer | E8: P027 | F8: 8811 | G8: 626 | H8: 2265.63 | I8: 42 | J8: 4421.58 | K8: 7.1 | L8: 6.71 | M8: 3.62 | N8: 53.94 | O8: 1.95
A9: 45259 | B9: Google Ads | C9: Campaign 39 | D9: Enterprise | E9: P015 | F9: 58314 | G9: 5300 | H9: 3129.37 | I9: 770 | J9: 29454.2 | K9: 9.09 | L9: 14.53 | M9: 0.59 | N9: 4.06 | O9: 9.41
A10: 45354 | B10: Google Ads | C10: Campaign 39 | D10: Agency | E10: P023 | F10: 133475 | G10: 1926 | H10: 8263.37 | I10: 411 | J10: 66844.01 | K10: 1.44 | L10: 21.34 | M10: 4.29 | N10: 20.11 | O10: 8.09
A11: 45343 | B11: Google Ads | C11: Campaign 2 | D11: Freelancer | E11: P011 | F11: 7956 | G11: 391 | H11: 312.98 | I11: 62 | J11: 5631.44 | K11: 4.91 | L11: 15.86 | M11: 0.8 | N11: 5.05 | O11: 17.99
A12: 45366 | B12: Google Ads | C12: Campaign 30 | D12: Small Business | E12: P022 | F12: 53124 | G12: 1205 | H12: 2928.42 | I12: 44 | J12: 8021.97 | K12: 2.27 | L12: 3.65 | M12: 2.43 | N12: 66.56 | O12: 2.74
A13: 45307 | B13: Google Ads | C13: Campaign 48 | D13: Small Business | E13: P004 | F13: 143853 | G13: 6117 | H13: 19062.66 | I13: 545 | J13: 57995.23 | K13: 4.25 | L13: 8.91 | M13: 3.12 | N13: 34.98 | O13: 3.04
... A3770: 45206 | B3770: Facebook | C3770: Campaign 40 | D3770: Enterprise | E3770: P024 | F3770: 59856 | G3770: 5631 | H3770: 2898.96 | I3770: 1165 | J3770: 124634.64 | K3770: 9.41 | L3770: 20.69 | M3770: 0.51 | N3770: 2.49 | O3770: 42.99
A3771: 45239 | B3771: Facebook | C3771: Campaign 32 | D3771: Enterprise | E3771: P019 | F3771: 1641 | G3771: 18 | H3771: 32.48 | I3771: 0 | J3771: 0 | K3771: 1.1 | L3771: 0 | M3771: 1.8 | O3771: 0
A3772: 45276 | B3772: Facebook | C3772: Campaign 18 | D3772: Agency | E3772: P004 | F3772: 69859 | G3772: 7135 | H3772: 16599.92 | I3772: 734 | J3772: 20724.95 | K3772: 10.21 | L3772: 10.29 | M3772: 2.33 | N3772: 22.62 | O3772: 1.25
A3773: 45231 | B3773: Facebook | C3773: Campaign 34 | D3773: Small Business | E3773: P014 | F3773: 124873 | G3773: 5059 | H3773: 4100.76 | I3773: 927 | J3773: 29081.63 | K3773: 4.05 | L3773: 18.32 | M3773: 0.81 | N3773: 4.42 | O3773: 7.09
A3774: 45306 | B3774: Facebook | C3774: Campaign 32 | D3774: Freelancer | E3774: P009 | F3774: 76415 | G3774: 6978 | H3774: 12596.93 | I3774: 508 | J3774: 65885.74 | K3774: 9.13 | L3774: 7.28 | M3774: 1.81 | N3774: 24.8 | O3774: 5.23
A3775: 45325 | B3775: Facebook | C3775: Campaign 14 | D3775: Freelancer | E3775: P004 | F3775: 48021 | G3775: 3422 | H3775: 6982.92 | I3775: 488 | J3775: 49189.03 | K3775: 7.13 | L3775: 14.26 | M3775: 2.04 | N3775: 14.31 | O3775: 7.04
A3776: 45207 | B3776: Facebook | C3776: Campaign 36 | D3776: Agency | E3776: P006 | F3776: 65159 | G3776: 3193 | H3776: 8596.04 | I3776: 501 | J3776: 5112.79 | K3776: 4.9 | L3776: 15.69 | M3776: 2.69 | N3776: 17.16 | O3776: 0.59
A3777: 45270 | B3777: Facebook | C3777: Campaign 34 | D3777: Freelancer | E3777: P024 | F3777: 32288 | G3777: 2342 | H3777: 1490.69 | I3777: 153 | J3777: 17487.78 | K3777: 7.25 | L3777: 6.53 | M3777: 0.64 | N3777: 9.74 | O3777: 11.73
A3778: 45217 | B3778: Facebook | C3778: Campaign 6 | D3778: Small Business | E3778: P026 | F3778: 130250 | G3778: 17010 | H3778: 68371.75 | I3778: 736 | J3778: 63829.96 | K3778: 13.06 | L3778: 4.33 | M3778: 4.02 | N3778: 92.9 | O3778: 0.93
A3779: 45348 | B3779: Facebook | C3779: Campaign 40 | D3779: Small Business | E3779: P002 | F3779: 95833 | G3779: 8580 | H3779: 8605.63 | I3779: 1505 | J3779: 225939.44 | K3779: 8.95 | L3779: 17.54 | M3779: 1 | N3779: 5.72 | O3779: 26.25
A3780: 45344 | B3780: Facebook | C3780: Campaign 35 | D3780: Freelancer | E3780: P001 | F3780: 126956 | G3780: 17264 | H3780: 7506.26 | I3780: 1228 | J3780: 204218.13 | K3780: 13.6 | L3780: 7.11 | M3780: 0.43 | N3780: 6.11 | O3780: 27.21
A3781: 45266 | B3781: Facebook | C3781: Campaign 15 | D3781: Small Business | E3781: P023 | F3781: 115312 | G3781: 11788 | H3781: 47941.78 | I3781: 481 | J3781: 58397.24 | K3781: 10.22 | L3781: 4.08 | M3781: 4.07 | N3781: 99.67 | O3781: 1.22
A3782: 45377 | B3782: Facebook | C3782: Campaign 20 | D3782: Small Business | E3782: P017 | F3782: 125791 | G3782: 11008 | H3782: 6013.29 | I3782: 1404 | J3782: 173894.47 | K3782: 8.75 | L3782: 12.75 | M3782: 0.55 | N3782: 4.28 | O3782: 28.92
A3783: 45295 | B3783: Facebook | C3783: Campaign 28 | D3783: Small Business | E3783: P004 | F3783: 32348 | G3783: 1058 | H3783: 1608.85 | I3783: 160 | J3783: 15410.99 | K3783: 3.27 | L3783: 15.12 | M3783: 1.52 | N3783: 10.06 | O3783: 9.58
... A4687: 45292 | B4687: Instagram | C4687: Campaign 28 | D4687: Agency | E4687: P012 | F4687: 2763 | G4687: 215 | H4687: 375.89 | I4687: 33 | J4687: 6568.03 | K4687: 7.78 | L4687: 15.35 | M4687: 1.75 | N4687: 11.39 | O4687: 17.47
A4688: 45218 | B4688: Instagram | C4688: Campaign 20 | D4688: Small Business | E4688: P030 | F4688: 3593 | G4688: 31 | H4688: 126.77 | I4688: 0 | J4688: 0 | K4688: 0.86 | L4688: 0 | M4688: 4.09 | O4688: 0
A4689: 45207 | B4689: Instagram | C4689: Campaign 16 | D4689: Agency | E4689: P006 | F4689: 94817 | G4689: 2792 | H4689: 9786.24 | I4689: 110 | J4689: 12422.25 | K4689: 2.94 | L4689: 3.94 | M4689: 3.51 | N4689: 88.97 | O4689: 1.27
A4690: 45229 | B4690: Instagram | C4690: Campaign 13 | D4690: Freelancer | E4690: P008 | F4690: 146409 | G4690: 6993 | H4690: 6629.7 | I4690: 1235 | J4690: 58534.41 | K4690: 4.78 | L4690: 17.66 | M4690: 0.95 | N4690: 5.37 | O4690: 8.83
A4691: 45274 | B4691: Instagram | C4691: Campaign 33 | D4691: Freelancer | E4691: P009 | F4691: 38329 | G4691: 1434 | H4691: 2190.89 | I4691: 202 | J4691: 26994.24 | K4691: 3.74 | L4691: 14.09 | M4691: 1.53 | N4691: 10.85 | O4691: 12.32
A4692: 45249 | B4692: Instagram | C4692: Campaign 3 | D4692: Agency | E4692: P018 | F4692: 116450 | G4692: 879 | H4692: 1223.27 | I4692: 98 | J4692: 6834.08 | K4692: 0.75 | L4692: 11.15 | M4692: 1.39 | N4692: 12.48 | O4692: 5.59
A4693: 45211 | B4693: Instagram | C4693: Campaign 15 | D4693: Enterprise | E4693: P010 | F4693: 95348 | G4693: 12700 | H4693: 46095.99 | I4693: 1891 | J4693: 134106.45 | K4693: 13.32 | L4693: 14.89 | M4693: 3.63 | N4693: 24.38 | O4693: 2.91
A4694: 45250 | B4694: Instagram | C4694: Campaign 16 | D4694: Freelancer | E4694: P025 | F4694: 8781 | G4694: 936 | H4694: 3611.95 | I4694: 133 | J4694: 21010.01 | K4694: 10.66 | L4694: 14.21 | M4694: 3.86 | N4694: 27.16 | O4694: 5.82
A4695: 45272 | B4695: Instagram | C4695: Campaign 30 | D4695: Agency | E4695: P026 | F4695: 52858 | G4695: 6005 | H4695: 16478.46 | I4695: 536 | J4695: 80629.15 | K4695: 11.36 | L4695: 8.93 | M4695: 2.74 | N4695: 30.74 | O4695: 4.89
A4696: 45256 | B4696: Instagram | C4696: Campaign 25 | D4696: Agency | E4696: P021 | F4696: 46651 | G4696: 1632 | H4696: 5868.51 | I4696: 298 | J4696: 49264.84 | K4696: 3.5 | L4696: 18.26 | M4696: 3.6 | N4696: 19.69 | O4696: 8.39
A4697: 45244 | B4697: Instagram | C4697: Campaign 14 | D4697: Small Business | E4697: P016 | F4697: 69681 | G4697: 5126 | H4697: 6095.69 | I4697: 250 | J4697: 37488.86 | K4697: 7.36 | L4697: 4.88 | M4697: 1.19 | N4697: 24.38 | O4697: 6.15
A4698: 45341 | B4698: Instagram | C4698: Campaign 1 | D4698: Enterprise | E4698: P017 | F4698: 90081 | G4698: 12026 | H4698: 36901.03 | I4698: 690 | J4698: 129240.32 | K4698: 13.35 | L4698: 5.74 | M4698: 3.07 | N4698: 53.48 | O4698: 3.5
A4699: 45245 | B4699: Instagram | C4699: Campaign 33 | D4699: Freelancer | E4699: P001 | F4699: 65478 | G4699: 9718 | H4699: 21154.65 | I4699: 1389 | J4699: 217461.23 | K4699: 14.84 | L4699: 14.29 | M4699: 2.18 | N4699: 15.23 | O4699: 10.28
...

Sheet Product_Categories
A1: Product ID | B1: Product Name | C1: Product Category
A2: P001 | B2: Analytics Pro | C2: Analytics
A3: P002 | B3: CRM Starter | C3: CRM
A4: P003 | B4: Cloud Backup | C4: Storage
A5: P004 | B5: Website Builder | C5: Website Tools
A6: P005 | B6: Ad Optimizer | C6: AdTech
A7: P006 | B7: Email Blast Pro | C7: Email Marketing
A8: P007 | B8: SEO Toolkit | C8: SEO
A9: P008 | B9: Social Media Manager | C9: Social Media
A10: P009 | B10: Landing Page Creator | C10: Website Tools
A11: P010 | B11: Affiliate Tracker | C11: Affiliate
A12: P011 | B12: Marketing Suite | C12: Marketing Suite
... A31: P030 | B31: Freemium Growth Kit | C31: Growth Tools

Sheet Clean_data
A1: Date | B1: Month | C1: Channel | D1: Campaign Name | E1: Customer Segment | F1: Product ID | G1: Product_Category | H1: Impressions | I1: Clicks | J1: Spend | K1: Conversions | L1: Revenue | M1: CTR (%) | N1: Conversion Rate (%) | O1: CPC ($) | P1: CPA ($) | Q1: ROAS
A2: 45200 | B2: =TEXT(A2, "mmm yyyy") -> Oct 2023 | C2: Facebook | D2: Campaign 5 | E2: Freelancer | F2: P015 | G2: =_xlfn.XLOOKUP(F2,Product_Categories!A:A,Product_Categories!C:C,"Missing") -> Audience Analytics | H2: 51739 | I2: 5780 | J2: 2497.91 | K2: 765 | L2: 122235.16 | M2: 11.17 | N2: 13.24 | O2: 0.43 | P2: 3.27 | Q2: 48.93
A3: 45200 | B3: =TEXT(A3, "mmm yyyy") -> Oct 2023 | C3: Email | D3: Campaign 30 | E3: Agency | F3: P012 | G3: =_xlfn.XLOOKUP(F3,Product_Categories!A:A,Product_Categories!C:C,"Missing") -> Planning | H3: 138464 | I3: 16111 | J3: 7678.96 | K3: 2867 | L3: 308849.74 | M3: 11.64 | N3: 17.8 | O3: 0.48 | P3: 2.68 | Q3: 40.22
A4: 45200 | B4: =TEXT(A4, "mmm yyyy") -> Oct 2023 | C4: Youtube | D4: Campaign 33 | E4: Freelancer | F4: P028 | G4: =_xlfn.XLOOKUP(F4,Product_Categories!A:A,Product_Categories!C:C,"Missing") -> Push Notifications | H4: 29484 | I4: 3138 | J4: 2476.56 | K4: 662 | L4: 99441.12 | M4: 10.64 | N4: 21.1 | O4: 0.79 | P4: 3.74 | Q4: 40.15
A5: 45200 | B5: =TEXT(A5, "mmm yyyy") -> Oct 2023 | C5: Email | D5: Campaign 17 | E5: Agency | F5: P008 | G5: =_xlfn.XLOOKUP(F5,Product_Categories!A:A,Product_Categories!C:C,"Missing") -> Social Media | H5: 29117 | I5: 3158 | J5: 1799.28 | K5: 359 | L5: 59071.67 | M5: 10.85 | N5: 11.37 | O5: 0.57 | P5: 5.01 | Q5: 32.83
A6: 45200 | B6: =TEXT(A6, "mmm yyyy") -> Oct 2023 | C6: Email | D6: Campaign 25 | E6: Enterprise | F6: P025 | G6: =_xlfn.XLOOKUP(F6,Product_Categories!A:A,Product_Categories!C:C,"Missing") -> Reporting | H6: 105065 | I6: 15309 | J6: 14581.12 | K6: 3042 | L6: 432777.25 | M6: 14.57 | N6: 19.87 | O6: 0.95 | P6: 4.79 | Q6: 29.68
A7: 45200 | B7: =TEXT(A7, "mmm yyyy") -> Oct 2023 | C7: Email | D7: Campaign 20 | E7: Agency | F7: P019 | G7: =_xlfn.XLOOKUP(F7,Product_Categories!A:A,Product_Categories!C:C,"Missing") -> Surveys | H7: 29150 | I7: 1163 | J7: 817.7 | K7: 212 | L7: 24175.75 | M7: 3.99 | N7: 18.23 | O7: 0.7 | P7: 3.86 | Q7: 29.57
A8: 45200 | B8: =TEXT(A8, "mmm yyyy") -> Oct 2023 | C8: Google Ads | D8: Campaign 35 | E8: Agency | F8: P008 | G8: =_xlfn.XLOOKUP(F8,Product_Categories!A:A,Product_Categories!C:C,"Missing") -> Social Media | H8: 25951 | I8: 1528 | J8: 773.08 | K8: 110 | L8: 17291.11 | M8: 5.89 | N8: 7.2 | O8: 0.51 | P8: 7.03 | Q8: 22.37
A9: 45200 | B9: =TEXT(A9, "mmm yyyy") -> Oct 2023 | C9: Facebook | D9: Campaign 50 | E9: Freelancer | F9: P010 | G9: =_xlfn.XLOOKUP(F9,Product_Categories!A:A,Product_Categories!C:C,"Missing") -> Affiliate | H9: 62474 | I9: 9309 | J9: 7772.8 | K9: 691 | L9: 131513.92 | M9: 14.9 | N9: 7.42 | O9: 0.83 | P9: 11.25 | Q9: 16.92
A10: 45200 | B10: =TEXT(A10, "mmm yyyy") -> Oct 2023 | C10: Facebook | D10: Campaign 28 | E10: Freelancer | F10: P005 | G10: =_xlfn.XLOOKUP(F10,Product_Categories!A:A,Product_Categories!C:C,"Missing") -> AdTech | H10: 3767 | I10: 377 | J10: 451.62 | K10: 39 | L10: 7393.62 | M10: 10.01 | N10: 10.34 | O10: 1.2 | P10: 11.58 | Q10: 16.37
A11: 45200 | B11: =TEXT(A11, "mmm yyyy") -> Oct 2023 | C11: Linkedin | D11: Campaign 34 | E11: Freelancer | F11: P017 | G11: =_xlfn.XLOOKUP(F11,Product_Categories!A:A,Product_Categories!C:C,"Missing") -> SEO | H11: 100932 | I11: 6691 | J11: 5322.68 | K11: 415 | L11: 81596.34 | M11: 6.63 | N11: 6.2 | O11: 0.8 | P11: 12.83 | Q11: 15.33
A12: 45200 | B12: =TEXT(A12, "mmm yyyy") -> Oct 2023 | C12: Email | D12: Campaign 11 | E12: Enterprise | F12: P023 | G12: =_xlfn.XLOOKUP(F12,Product_Categories!A:A,Product_Categories!C:C,"Missing") -> UX | H12: 13806 | I12: 1135 | J12: 3219.66 | K12: 247 | L12: 48678.28 | M12: 8.22 | N12: 21.76 | O12: 2.84 | P12: 13.04 | Q12: 15.12
A13: 45200 | B13: =TEXT(A13, "mmm yyyy") -> Oct 2023 | C13: Youtube | D13: Campaign 24 | E13: Small Business | F13: P011 | G13: =_xlfn.XLOOKUP(F13,Product_Categories!A:A,Product_Categories!C:C,"Missing") -> Marketing Suite | H13: 123691 | I13: 11902 | J13: 18336.07 | K13: 1836 | L13: 258216.02 | M13: 9.62 | N13: 15.43 | O13: 1.54 | P13: 9.99 | Q13: 14.08
... A1234: 45218 | B1234: =TEXT(A1234, "mmm yyyy") -> Oct 2023 | C1234: Youtube | D1234: Campaign 7 | E1234: Freelancer | F1234: P008 | G1234: =_xlfn.XLOOKUP(F1234,Product_Categories!A:A,Product_Categories!C:C,"Missing") -> Social Media | H1234: 92582 | I1234: 3907 | J1234: 15826.12 | K1234: 201 | L1234: 1713.95 | M1234: 4.22 | N1234: 5.14 | O1234: 4.05 | P1234: 78.74 | Q1234: 0.11
A1235: 45218 | B1235: =TEXT(A1235, "mmm yyyy") -> Oct 2023 | C1235: Instagram | D1235: Campaign 20 | E1235: Small Business | F1235: P030 | G1235: =_xlfn.XLOOKUP(F1235,Product_Categories!A:A,Product_Categories!C:C,"Missing") -> Growth Tools | H1235: 3593 | I1235: 31 | J1235: 126.77 | K1235: 0 | L1235: 0 | M1235: 0.86 | N1235: 0 | O1235: 4.09 | Q1235: 0
A1236: 45219 | B1236: =TEXT(A1236, "mmm yyyy") -> Oct 2023 | C1236: Facebook | D1236: Campaign 11 | E1236: Small Business | F1236: P006 | G1236: =_xlfn.XLOOKUP(F1236,Product_Categories!A:A,Product_Categories!C:C,"Missing") -> Email Marketing | H1236: 26253 | I1236: 2283 | J1236: 1812.5 | K1236: 430 | L1236: 65248.69 | M1236: 8.7 | N1236: 18.83 | O1236: 0.79 | P1236: 4.22 | Q1236: 36
A1237: 45219 | B1237: =TEXT(A1237, "mmm yyyy") -> Oct 2023 | C1237: Linkedin | D1237: Campaign 36 | E1237: Small Business | F1237: P014 | G1237: =_xlfn.XLOOKUP(F1237,Product_Categories!A:A,Product_Categories!C:C,"Missing") -> Lead Management | H1237: 94604 | I1237: 10438 | J1237: 6700.69 | K1237: 1372 | L1237: 216335.55 | M1237: 11.03 | N1237: 13.14 | O1237: 0.64 | P1237: 4.88 | Q1237: 32.29
A1238: 45219 | B1238: =TEXT(A1238, "mmm yyyy") -> Oct 2023 | C1238: Facebook | D1238: Campaign 30 | E1238: Freelancer | F1238: P022 | G1238: =_xlfn.XLOOKUP(F1238,Product_Categories!A:A,Product_Categories!C:C,"Missing") -> Budgeting | H1238: 121715 | I1238: 14427 | J1238: 16463.82 | K1238: 2626 | L1238: 341744.29 | M1238: 11.85 | N1238: 18.2 | O1238: 1.14 | P1238: 6.27 | Q1238: 20.76
A1239: 45219 | B1239: =TEXT(A1239, "mmm yyyy") -> Oct 2023 | C1239: Youtube | D1239: Campaign 41 | E1239: Agency | F1239: P007 | G1239: =_xlfn.XLOOKUP(F1239,Product_Categories!A:A,Product_Categories!C:C,"Missing") -> SEO | H1239: 46323 | I1239: 1749 | J1239: 2152.14 | K1239: 248 | L1239: 37062.79 | M1239: 3.78 | N1239: 14.18 | O1239: 1.23 | P1239: 8.68 | Q1239: 17.22
A1240: 45219 | B1240: =TEXT(A1240, "mmm yyyy") -> Oct 2023 | C1240: Facebook | D1240: Campaign 19 | E1240: Freelancer | F1240: P025 | G1240: =_xlfn.XLOOKUP(F1240,Product_Categories!A:A,Product_Categories!C:C,"Missing") -> Reporting | H1240: 90651 | I1240: 11046 | J1240: 10406.07 | K1240: 1829 | L1240: 164445.47 | M1240: 12.19 | N1240: 16.56 | O1240: 0.94 | P1240: 5.69 | Q1240: 15.8
A1241: 45219 | B1241: =TEXT(A1241, "mmm yyyy") -> Oct 2023 | C1241: Google Ads | D1241: Campaign 43 | E1241: Enterprise | F1241: P021 | G1241: =_xlfn.XLOOKUP(F1241,Product_Categories!A:A,Product_Categories!C:C,"Missing") -> Feedback | H1241: 116309 | I1241: 14508 | J1241: 13468.74 | K1241: 1359 | L1241: 203828.41 | M1241: 12.47 | N1241: 9.37 | O1241: 0.93 | P1241: 9.91 | Q1241: 15.13
A1242: 45219 | B1242: =TEXT(A1242, "mmm yyyy") -> Oct 2023 | C1242: Facebook | D1242: Campaign 50 | E1242: Freelancer | F1242: P014 | G1242: =_xlfn.XLOOKUP(F1242,Product_Categories!A:A,Product_Categories!C:C,"Missing") -> Lead Management | H1242: 30287 | I1242: 246 | J1242: 333.55 | K1242: 42 | L1242: 5010.25 | M1242: 0.81 | N1242: 17.07 | O1242: 1.36 | P1242: 7.94 | Q1242: 15.02
A1243: 45219 | B1243: =TEXT(A1243, "mmm yyyy") -> Oct 2023 | C1243: Google Ads | D1243: Campaign 13 | E1243: Agency | F1243: P018 | G1243: =_xlfn.XLOOKUP(F1243,Product_Categories!A:A,Product_Categories!C:C,"Missing") -> Conversion | H1243: 9866 | I1243: 453 | J1243: 699.4 | K1243: 48 | L1243: 9588.7 | M1243: 4.59 | N1243: 10.6 | O1243: 1.54 | P1243: 14.57 | Q1243: 13.71
A1244: 45219 | B1244: =TEXT(A1244, "mmm yyyy") -> Oct 2023 | C1244: Google Ads | D1244: Campaign 13 | E1244: Agency | F1244: P030 | G1244: =_xlfn.XLOOKUP(F1244,Product_Categories!A:A,Product_Categories!C:C,"Missing") -> Growth Tools | H1244: 45074 | I1244: 6412 | J1244: 5348.98 | K1244: 380 | L1244: 71904.96 | M1244: 14.23 | N1244: 5.93 | O1244: 0.83 | P1244: 14.08 | Q1244: 13.44
A1245: 45219 | B1245: =TEXT(A1245, "mmm yyyy") -> Oct 2023 | C1245: Email | D1245: Campaign 45 | E1245: Freelancer | F1245: P017 | G1245: =_xlfn.XLOOKUP(F1245,Product_Categories!A:A,Product_Categories!C:C,"Missing") -> SEO | H1245: 98732 | I1245: 3091 | J1245: 4792.54 | K1245: 400 | L1245: 63568.71 | M1245: 3.13 | N1245: 12.94 | O1245: 1.55 | P1245: 11.98 | Q1245: 13.26
A1246: 45219 | B1246: =TEXT(A1246, "mmm yyyy") -> Oct 2023 | C1246: Instagram | D1246: Campaign 5 | E1246: Small Business | F1246: P018 | G1246: =_xlfn.XLOOKUP(F1246,Product_Categories!A:A,Product_Categories!C:C,"Missing") -> Conversion | H1246: 53051 | I1246: 7041 | J1246: 6919.9 | K1246: 1112 | L1246: 90388.55 | M1246: 13.27 | N1246: 15.79 | O1246: 0.98 | P1246: 6.22 | Q1246: 13.06
A1247: 45219 | B1247: =TEXT(A1247, "mmm yyyy") -> Oct 2023 | C1247: Linkedin | D1247: Campaign 19 | E1247: Freelancer | F1247: P017 | G1247: =_xlfn.XLOOKUP(F1247,Product_Categories!A:A,Product_Categories!C:C,"Missing") -> SEO | H1247: 64690 | I1247: 7429 | J1247: 17553.56 | K1247: 1262 | L1247: 222896.31 | M1247: 11.48 | N1247: 16.99 | O1247: 2.36 | P1247: 13.91 | Q1247: 12.7
... A2669: 45239 | B2669: =TEXT(A2669, "mmm yyyy") -> Nov 2023 | C2669: Linkedin | D2669: Campaign 6 | E2669: Enterprise | F2669: P003 | G2669: =_xlfn.XLOOKUP(F2669,Product_Categories!A:A,Product_Categories!C:C,"Missing") -> Storage | H2669: 100623 | I2669: 9842 | J2669: 34015.88 | K2669: 437 | L2669: 7947.78 | M2669: 9.78 | N2669: 4.44 | O2669: 3.46 | P2669: 77.84 | Q2669: 0.23
A2670: 45239 | B2670: =TEXT(A2670, "mmm yyyy") -> Nov 2023 | C2670: Facebook | D2670: Campaign 32 | E2670: Enterprise | F2670: P019 | G2670: =_xlfn.XLOOKUP(F2670,Product_Categories!A:A,Product_Categories!C:C,"Missing") -> Surveys | H2670: 1641 | I2670: 18 | J2670: 32.48 | K2670: 0 | L2670: 0 | M2670: 1.1 | N2670: 0 | O2670: 1.8 | Q2670: 0
A2671: 45240 | B2671: =TEXT(A2671, "mmm yyyy") -> Nov 2023 | C2671: Google Ads | D2671: Campaign 9 | E2671: Freelancer | F2671: P005 | G2671: =_xlfn.XLOOKUP(F2671,Product_Categories!A:A,Product_Categories!C:C,"Missing") -> AdTech | H2671: 22282 | I2671: 2347 | J2671: 1538.22 | K2671: 297 | L2671: 59208.7 | M2671: 10.53 | N2671: 12.65 | O2671: 0.66 | P2671: 5.18 | Q2671: 38.49
A2672: 45240 | B2672: =TEXT(A2672, "mmm yyyy") -> Nov 2023 | C2672: Linkedin | D2672: Campaign 27 | E2672: Agency | F2672: P021 | G2672: =_xlfn.XLOOKUP(F2672,Product_Categories!A:A,Product_Categories!C:C,"Missing") -> Feedback | H2672: 103560 | I2672: 14069 | J2672: 17199.43 | K2672: 2452 | L2672: 339628.91 | M2672: 13.59 | N2672: 17.43 | O2672: 1.22 | P2672: 7.01 | Q2672: 19.75
A2673: 45240 | B2673: =TEXT(A2673, "mmm yyyy") -> Nov 2023 | C2673: Google Ads | D2673: Campaign 12 | E2673: Freelancer | F2673: P003 | G2673: =_xlfn.XLOOKUP(F2673,Product_Categories!A:A,Product_Categories!C:C,"Missing") -> Storage | H2673: 41784 | I2673: 3374 | J2673: 2105.38 | K2673: 725 | L2673: 35593.47 | M2673: 8.07 | N2673: 21.49 | O2673: 0.62 | P2673: 2.9 | Q2673: 16.91
A2674: 45240 | B2674: =TEXT(A2674, "mmm yyyy") -> Nov 2023 | C2674: Linkedin | D2674: Campaign 43 | E2674: Small Business | F2674: P004 | G2674: =_xlfn.XLOOKUP(F2674,Product_Categories!A:A,Product_Categories!C:C,"Missing") -> Website Tools | H2674: 12084 | I2674: 1702 | J2674: 3886.79 | K2674: 362 | L2674: 53859.88 | M2674: 14.08 | N2674: 21.27 | O2674: 2.28 | P2674: 10.74 | Q2674: 13.86
A2675: 45240 | B2675: =TEXT(A2675, "mmm yyyy") -> Nov 2023 | C2675: Email | D2675: Campaign 41 | E2675: Enterprise | F2675: P011 | G2675: =_xlfn.XLOOKUP(F2675,Product_Categories!A:A,Product_Categories!C:C,"Missing") -> Marketing Suite | H2675: 46106 | I2675: 6004 | J2675: 3848.18 | K2675: 1267 | L2675: 52667.38 | M2675: 13.02 | N2675: 21.1 | O2675: 0.64 | P2675: 3.04 | Q2675: 13.69
A2676: 45240 | B2676: =TEXT(A2676, "mmm yyyy") -> Nov 2023 | C2676: Youtube | D2676: Campaign 11 | E2676: Small Business | F2676: P014 | G2676: =_xlfn.XLOOKUP(F2676,Product_Categories!A:A,Product_Categories!C:C,"Missing") -> Lead Management | H2676: 105088 | I2676: 3541 | J2676: 8117.28 | K2676: 572 | L2676: 110485.58 | M2676: 3.37 | N2676: 16.15 | O2676: 2.29 | P2676: 14.19 | Q2676: 13.61
A2677: 45240 | B2677: =TEXT(A2677, "mmm yyyy") -> Nov 2023 | C2677: Youtube | D2677: Campaign 21 | E2677: Agency | F2677: P012 | G2677: =_xlfn.XLOOKUP(F2677,Product_Categories!A:A,Product_Categories!C:C,"Missing") -> Planning | H2677: 11715 | I2677: 1166 | J2677: 620.79 | K2677: 57 | L2677: 8322.74 | M2677: 9.95 | N2677: 4.89 | O2677: 0.53 | P2677: 10.89 | Q2677: 13.41
A2678: 45240 | B2678: =TEXT(A2678, "mmm yyyy") -> Nov 2023 | C2678: Google Ads | D2678: Campaign 17 | E2678: Enterprise | F2678: P006 | G2678: =_xlfn.XLOOKUP(F2678,Product_Categories!A:A,Product_Categories!C:C,"Missing") -> Email Marketing | H2678: 140231 | I2678: 4399 | J2678: 7994.02 | K2678: 881 | L2678: 85829.24 | M2678: 3.14 | N2678: 20.03 | O2678: 1.82 | P2678: 9.07 | Q2678: 10.74
A2679: 45240 | B2679: =TEXT(A2679, "mmm yyyy") -> Nov 2023 | C2679: Google Ads | D2679: Campaign 49 | E2679: Agency | F2679: P005 | G2679: =_xlfn.XLOOKUP(F2679,Product_Categories!A:A,Product_Categories!C:C,"Missing") -> AdTech | H2679: 144287 | I2679: 13253 | J2679: 11546.35 | K2679: 633 | L2679: 115444.79 | M2679: 9.19 | N2679: 4.78 | O2679: 0.87 | P2679: 18.24 | Q2679: 10
A2680: 45240 | B2680: =TEXT(A2680, "mmm yyyy") -> Nov 2023 | C2680: Google Ads | D2680: Campaign 47 | E2680: Agency | F2680: P013 | G2680: =_xlfn.XLOOKUP(F2680,Product_Categories!A:A,Product_Categories!C:C,"Missing") -> Webinars | H2680: 16705 | I2680: 800 | J2680: 323.65 | K2680: 65 | L2680: 3086.77 | M2680: 4.79 | N2680: 8.12 | O2680: 0.4 | P2680: 4.98 | Q2680: 9.54
A2681: 45240 | B2681: =TEXT(A2681, "mmm yyyy") -> Nov 2023 | C2681: Linkedin | D2681: Campaign 8 | E2681: Enterprise | F2681: P006 | G2681: =_xlfn.XLOOKUP(F2681,Product_Categories!A:A,Product_Categories!C:C,"Missing") -> Email Marketing | H2681: 148295 | I2681: 9043 | J2681: 16208.55 | K2681: 841 | L2681: 150982.62 | M2681: 6.1 | N2681: 9.3 | O2681: 1.79 | P2681: 19.27 | Q2681: 9.31
...

Sheet Channel Performance Summary
B2: Row Labels | C2: Sum of Spend | D2: Sum of Revenue | E2: Average of ROAS | F2: Average of CTR (%) | G2: Average of Conversion Rate (%)
B3: Email | C3: 27994295 | D3: 1.4949151e+08 | E3: 7.694965 | F3: 7.70788 | G3: 12.37328
B4: Facebook | C4: 28290606 | D4: 1.502229e+08 | E4: 7.496705 | F4: 7.69677 | G4: 12.59032
B5: Google Ads | C5: 29830823 | D5: 1.4899173e+08 | E5: 7.51143 | F5: 7.73387 | G5: 12.235735
B6: Instagram | C6: 29202080 | D6: 1.5499026e+08 | E6: 7.75324 | F6: 7.836305 | G6: 12.789055
B7: Linkedin | C7: 28315442 | D7: 1.4986667e+08 | E7: 7.7001 | F7: 7.73885 | G7: 12.307985
B8: Youtube | C8: 28100472 | D8: 1.4876113e+08 | E8: 7.3212 | F8: 7.708265 | G8: 12.446985
B9: Grand Total | C9: 1.7173372e+08 | D9: 9.0232419e+08 | E9: 7.5796067 | F9: 7.73699 | G9: 12.457227

Sheet Monthly Spend & Revenue Trend
C2: Column Labels
C3: Email | E3: Facebook | G3: Google Ads | I3: Instagram | K3: Linkedin | M3: Youtube | O3: Total Sum of Spend | P3: Total Sum of Revenue
B4: Row Labels | C4: Sum of Spend | D4: Sum of Revenue | E4: Sum of Spend | F4: Sum of Revenue | G4: Sum of Spend | H4: Sum of Revenue | I4: Sum of Spend | J4: Sum of Revenue | K4: Sum of Spend | L4: Sum of Revenue | M4: Sum of Spend | N4: Sum of Revenue
B5: Dec 2023 | C5: 4844694.1 | D5: 26172785 | E5: 4835422.7 | F5: 24816664 | G5: 5356823.5 | H5: 28906764 | I5: 5002585 | J5: 24512032 | K5: 5285570.3 | L5: 28885121 | M5: 4871127.9 | N5: 25950808 | O5: 30196223 | P5: 1.5924417e+08
B6: Feb 2024 | C6: 4137181.9 | D6: 23175412 | E6: 4834354 | F6: 25624871 | G6: 4966006.9 | H6: 20894874 | I6: 3746596.2 | J6: 19415813 | K6: 4321302.7 | L6: 22064652 | M6: 4706381.6 | N6: 24925115 | O6: 26711823 | P6: 1.3610074e+08
B7: Jan 2024 | C7: 4861522.8 | D7: 25046783 | E7: 4832201.9 | F7: 28622194 | G7: 5459668.1 | H7: 27028141 | I7: 4916393.6 | J7: 30615717 | K7: 5004552.9 | L7: 27335245 | M7: 5192720.1 | N7: 26753947 | O7: 30267059 | P7: 1.6540203e+08
B8: Mar 2024 | C8: 4625934.8 | D8: 25633568 | E8: 5268591.8 | F8: 26621955 | G8: 4532789.5 | H8: 20561540 | I8: 5121469.3 | J8: 26666192 | K8: 4080678.9 | L8: 21353660 | M8: 3961970.4 | N8: 22325898 | O8: 27591435 | P8: 1.4316281e+08
B9: Nov 2023 | C9: 4379974.5 | D9: 22642635 | E9: 4142454.2 | F9: 21221359 | G9: 4556843 | H9: 24327395 | I9: 5059829.4 | J9: 25955183 | K9: 4818315.2 | L9: 24642461 | M9: 5025230.5 | N9: 26666065 | O9: 27982647 | P9: 1.454551e+08
B10: Oct 2023 | C10: 5144986.4 | D10: 26820324 | E10: 4377581.4 | F10: 23315853 | G10: 4958692.2 | H10: 27273014 | I10: 5355207 | J10: 27825322 | K10: 4805022.1 | L10: 25585526 | M10: 4343041.8 | N10: 22139296 | O10: 28984531 | P10: 1.5295934e+08
B11: Grand Total | C11: 27994295 | D11: 1.4949151e+08 | E11: 28290606 | F11: 1.502229e+08 | G11: 29830823 | H11: 1.4899173e+08 | I11: 29202080 | J11: 1.5499026e+08 | K11: 28315442 | L11: 1.4986667e+08 | M11: 28100472 | N11: 1.4876113e+08 | O11: 1.7173372e+08 | P11: 9.0232419e+08

Sheet Product Category Analysis
B2: Row Labels | C2: Sum of Revenue | D2: Sum of Conversions | E2: Average of ROAS
B3: AdTech | C3: 32110797 | D3: 301403 | E3: 7.4535236
B4: Affiliate | C4: 28479096 | D4: 276053 | E4: 7.7068878
B5: Analytics | C5: 31409949 | D5: 291850 | E5: 7.5754455
B6: Audience Analytics | C6: 26818865 | D6: 291422 | E6: 6.9180299
B7: Automation | C7: 32317030 | D7: 307673 | E7: 7.5966912
B8: Brand Monitoring | C8: 32690534 | D8: 315194 | E8: 7.1737644
B9: Budgeting | C9: 31368774 | D9: 303949 | E9: 7.0971084
B10: Conversion | C10: 29979667 | D10: 307553 | E10: 7.8696599
B11: CRM | C11: 28989091 | D11: 278680 | E11: 7.241335
B12: Design | C12: 27860499 | D12: 274019 | E12: 7.9291599
B13: Email Marketing | C13: 29693617 | D13: 309285 | E13: 7.1623393
B14: Feedback | C14: 33454452 | D14: 302447 | E14: 8.0710941
... B31: Grand Total | C31: 9.0232419e+08 | D31: 8800593 | E31: 7.5796067

Sheet Customer Segment Performance
B2: Row Labels | C2: Sum of Revenue | D2: Average of ROAS | E2: Average of CTR (%) | F2: Average of CPA ($)
B3: Agency | C3: 2.1343427e+08 | D3: 7.6120839 | E3: 7.6815595 | F3: 25.969367
B4: Enterprise | C4: 2.2486004e+08 | D4: 7.3756928 | E4: 7.8294444 | F4: 25.407523
B5: Freelancer | C5: 2.3240922e+08 | D5: 7.5604244 | E5: 7.6965252 | F5: 25.220003
B6: Small Business | C6: 2.3162065e+08 | D6: 7.7674836 | E6: 7.7401612 | F6: 25.832854
B7: Grand Total | C7: 9.0232419e+08 | D7: 7.5796067 | E7: 7.73699 | F7: 25.606523

Sheet Campaign Performance
B7: Row Labels | C7: Sum of Spend | D7: Sum of Revenue | E7: Sum of Conversions | F7: Average of ROAS | G7: Average of CPA ($)
B8: Campaign 18 | C8: 3079742.2 | D8: 17670444 | E8: 166604 | F8: 8.8248611 | G8: 22.085278
B9: Campaign 28 | C9: 3130575.3 | D9: 18938701 | E9: 168101 | F9: 8.7212821 | G9: 22.909103
B10: Campaign 2 | C10: 3168220.1 | D10: 17801623 | E10: 175199 | F10: 8.7090717 | G10: 24.39557
B11: Campaign 45 | C11: 3732152.7 | D11: 21745661 | E11: 195559 | F11: 8.4358935 | G11: 25.36749
B12: Campaign 19 | C12: 3089768.6 | D12: 17031021 | E12: 166325 | F12: 8.3985096 | G12: 25.315144
B13: Campaign 41 | C13: 3187090.9 | D13: 17046138 | E13: 168272 | F13: 8.3222041 | G13: 25.684204
B14: Campaign 14 | C14: 3146200.4 | D14: 18818625 | E14: 174244 | F14: 8.2388477 | G14: 23.808107
B15: Campaign 4 | C15: 3204888.6 | D15: 18451730 | E15: 173584 | F15: 8.2020614 | G15: 23.364605
B16: Campaign 10 | C16: 3583995.1 | D16: 18892397 | E16: 183418 | F16: 8.1793694 | G16: 27.435811
B17: Campaign 40 | C17: 3413941.7 | D17: 19081202 | E17: 171589 | F17: 8.168412 | G17: 26.032318
B18: Campaign 11 | C18: 3678481.9 | D18: 20849811 | E18: 192250 | F18: 8.1675391 | G18: 25.598633
B19: Campaign 49 | C19: 3588874.7 | D19: 19837778 | E19: 194737 | F19: 8.1675294 | G19: 25.999137
... B58: Grand Total | C58: 1.7173372e+08 | D58: 9.0232419e+08 | E58: 8800593 | F58: 7.5796067 | G58: 25.606523

Sheet Dashboard
N2: ="$" & TEXT(SUM(Clean_data!L2:L12001)/1000000,"#,##0.0") & "M" -> $902.3M | O2: =TEXT(AVERAGE(Clean_data!Q2:Q12001),"0.00") -> 7.58 | P2: =TEXT(MIN(Clean_data!P2:P1234),"$0.00") -> $2.11 | Q2: =TEXT(SUM(Clean_data!K2:K12001)/1000000,"#,##0.0") & "M" -> 8.8M | R2: =_xlfn.XLOOKUP(MAX(Clean_data!M2:M12001), Clean_data!M2:M12001, Clean_data!D2:D12001) & " (" & TEXT(MAX(Clean_data!M2:M12001),"0.00") & ")" -> Campaign 46 (15.00)

Sheet Top 5 Product
B2: Row Labels | C2: Sum of Revenue
B3: Feedback | C3: 33454452
B4: Mobile Ads | C4: 34049084
B5: SEO | C5: 61260958
B6: Surveys | C6: 36342667
B7: Website Tools | C7: 58682382
B8: Grand Total | C8: 2.2378954e+08

Sheet ROAS_Channel
B2: Row Labels | C2: Average ROAS by Channel
B3: Instagram | C3: 7.75324
B4: Linkedin | C4: 7.7001
B5: Email | C5: 7.694965
B6: Google Ads | C6: 7.51143
B7: Facebook | C7: 7.496705
B8: Youtube | C8: 7.3212
B9: Grand Total | C9: 7.5796067

Sheet Average ROAS by Channel
B3: Sum of Spend | C3: Column Labels
B4: Row Labels | C4: Email | D4: Facebook | E4: Google Ads | F4: Instagram | G4: Linkedin | H4: Youtube | I4: Grand Total
B5: 2023 | C5: 14369655 | D5: 13355458 | E5: 14872359 | F5: 15417621 | G5: 14908908 | H5: 14239400 | I5: 87163401
B6: Oct | C6: 5144986.4 | D6: 4377581.4 | E6: 4958692.2 | F6: 5355207 | G6: 4805022.1 | H6: 4343041.8 | I6: 28984531
B7: Nov | C7: 4379974.5 | D7: 4142454.2 | E7: 4556843 | F7: 5059829.4 | G7: 4818315.2 | H7: 5025230.5 | I7: 27982647
B8: Dec | C8: 4844694.1 | D8: 4835422.7 | E8: 5356823.5 | F8: 5002584.9 | G8: 5285570.3 | H8: 4871127.9 | I8: 30196223
B9: 2024 | C9: 13624640 | D9: 14935148 | E9: 14958465 | F9: 13784459 | G9: 13406535 | H9: 13861072 | I9: 84570318
B10: Jan | C10: 4861522.8 | D10: 4832201.9 | E10: 5459668.1 | F10: 4916393.6 | G10: 5004552.9 | H10: 5192720.1 | I10: 30267059
B11: Feb | C11: 4137181.9 | D11: 4834354 | E11: 4966006.9 | F11: 3746596.2 | G11: 4321302.7 | H11: 4706381.6 | I11: 26711823
B12: Mar | C12: 4625934.8 | D12: 5268591.8 | E12: 4532789.5 | F12: 5121469.3 | G12: 4080678.9 | H12: 3961970.4 | I12: 27591435
B13: Grand Total | C13: 27994295 | D13: 28290606 | E13: 29830823 | F13: 29202080 | G13: 28315442 | H13: 28100472 | I13: 1.7173372e+08

Sheet ROAS vs CPA
B2: Campaign Name | C2: Average of CPA ($) | D2: Average of ROAS | E2: Sum of Conversions
B3: Campaign 9 | C3: 22.498605 | D3: 7.4443798 | E3: 217854
B4: Campaign 34 | C4: 25.785234 | D4: 7.6251953 | E4: 210305
B5: Campaign 45 | C5: 25.36749 | D5: 8.4358935 | E5: 195559
B6: Campaign 49 | C6: 25.999137 | D6: 8.1675294 | E6: 194737
B7: Campaign 46 | C7: 27.58072 | D7: 7.40216 | E7: 192516
B8: Campaign 11 | C8: 25.598633 | D8: 8.1675391 | E8: 192250
B9: Campaign 31 | C9: 25.56749 | D9: 7.4573684 | E9: 190034
B10: Campaign 1 | C10: 25.943042 | D10: 7.2708365 | E10: 188359
B11: Campaign 25 | C11: 26.190239 | D11: 7.0839841 | E11: 188146
B12: Campaign 23 | C12: 24.437347 | D12: 7.1964082 | E12: 186490
B13: Campaign 12 | C13: 25.535935 | D13: 7.4486992 | E13: 186427
B14: Campaign 24 | C14: 26.392898 | D14: 7.1354286 | E14: 184554
... B17: Campaign 33 | C17: 25.561197 | D17: 7.6964865 | E17: 179963
